<?xml version="1.0" ?>
<robot name="drchubo_left_gripper_v3">
<link name="Body_LWP">
        <visual>
            <geometry>
                <mesh filename="package://drchubo_v3/meshes/convhull_LWP_merged.stl"/>
            </geometry>
            <origin rpy="0 0 0" xyz="0 0 0"/>
            <material name="">
                <color rgba="0.3 0.3 0.3 1.0"/>
            </material>
        </visual>
        <collision>
            <geometry>
                <mesh filename="package://drchubo_v3/meshes/convhull_LWP_merged.stl"/>
            </geometry>
            <origin rpy="0 0 0" xyz="0 0 0"/>
        </collision>
        <inertial>
            <mass value="0.327632198289"/>
            <inertia ixx="0.000346968656319" ixy="5.89262498623e-05" ixz="4.30826482069e-06" iyy="0.00057562979027" iyz="-1.25504736046e-06" izz="0.000744124634836"/>
            <origin rpy="0 0 0" xyz="-0.0145320131223 -0.0546994779181 -0.000367800192129"/>
        </inertial>
    </link>

<link name="Body_LWR">
        <visual>
            <geometry>
                <mesh filename="package://drchubo_v3/meshes/convhull_LWR_merged.stl"/>
            </geometry>
            <origin rpy="0 0 0" xyz="0 0 0"/>
            <material name="">
                <color rgba="0.3 0.3 0.3 1.0"/>
            </material>
        </visual>
        <collision>
            <geometry>
                <mesh filename="package://drchubo_v3/meshes/convhull_LWR_merged.stl"/>
            </geometry>
            <origin rpy="0 0 0" xyz="0 0 0"/>
        </collision>
        <inertial>
            <mass value="1.26227162553"/>
            <inertia ixx="0.00137019038629" ixy="6.08173568367e-05" ixz="5.84193124812e-06" iyy="0.00133077281236" iyz="-1.17164831963e-05" izz="0.00120357514264"/>
            <origin rpy="0 0 0" xyz="0.0461316332402 -0.000476271776753 0.0008021254173"/>
        </inertial>
    </link>
    <link name="leftPalm">
        <inertial>
            <mass value="0.1"/>
            <inertia ixx="0.0001" ixy="0" ixz="0" iyy="0.0001" iyz="0" izz="0.0001"/>
            <origin rpy="0 0 0" xyz="0 0 0"/>
        </inertial>
    </link>
    <joint name="LWR_dummy" type="fixed">
        <parent link="Body_LWR"/>
        <child link="leftPalm"/>
        <origin rpy="0 0 1.57079632679" xyz="0.1 0 0"/>
    </joint>
<link name="Body_LF11">
        <visual>
            <geometry>
                <mesh filename="package://drchubo_v3/meshes/convhull_LF11.stl"/>
            </geometry>
            <origin rpy="0 0 0" xyz="0 0 0"/>
            <material name="">
                <color rgba="0.3 0.3 0.3 1.0"/>
            </material>
        </visual>
        <collision>
            <geometry>
                <mesh filename="package://drchubo_v3/meshes/convhull_LF11.stl"/>
            </geometry>
            <origin rpy="0 0 0" xyz="0 0 0"/>
        </collision>
        <inertial>
            <mass value="0.0263710648328"/>
            <inertia ixx="1.98396439062e-06" ixy="3.66951330319e-08" ixz="-7.82216813087e-08" iyy="6.90160086478e-06" iyz="-5.52885566501e-09" izz="6.59611827284e-06"/>
            <origin rpy="0 0 0" xyz="0.013675535045 0.000167665760228 0.000198749511991"/>
        </inertial>
    </link>
    <link name="Body_LF12">
        <visual>
            <geometry>
                <mesh filename="package://drchubo_v3/meshes/convhull_LF12_merged.stl"/>
            </geometry>
            <origin rpy="0 0 0" xyz="0 0 0"/>
            <material name="">
                <color rgba="0.3 0.3 0.3 1.0"/>
            </material>
        </visual>
        <collision>
            <geometry>
                <mesh filename="package://drchubo_v3/meshes/convhull_LF12_merged.stl"/>
            </geometry>
            <origin rpy="0 0 0" xyz="0 0 0"/>
        </collision>
        <inertial>
            <mass value="0.016189368249"/>
            <inertia ixx="1.30911370818e-06" ixy="1.49423602565e-08" ixz="-5.01486524729e-08" iyy="2.82043860524e-06" iyz="-2.8629444527e-09" izz="3.05888536891e-06"/>
            <origin rpy="0 0 0" xyz="0.0110393059886 0.000234060880175 5.56986057553e-05"/>
        </inertial>
    </link>
    <link name="Body_LF13">
        <visual>
            <geometry>
                <mesh filename="package://drchubo_v3/meshes/convhull_LF13_merged.stl"/>
            </geometry>
            <origin rpy="0 0 0" xyz="0 0 0"/>
            <material name="">
                <color rgba="0.3 0.3 0.3 1.0"/>
            </material>
        </visual>
        <collision>
            <geometry>
                <mesh filename="package://drchubo_v3/meshes/convhull_LF13_merged.stl"/>
            </geometry>
            <origin rpy="0 0 0" xyz="0 0 0"/>
        </collision>
        <inertial>
            <mass value="0.0182221650877"/>
            <inertia ixx="1.03181617487e-06" ixy="-4.94978359879e-08" ixz="-1.22492186704e-07" iyy="2.57254536616e-06" iyz="-5.58418574879e-09" izz="2.54656084717e-06"/>
            <origin rpy="0 0 0" xyz="0.0171497739791 -0.000431859131656 0.000224831410368"/>
        </inertial>
    </link>
    <joint name="LF1" type="revolute">
        <parent link="Body_LWR"/>
        <child link="Body_LF11"/>
        <origin rpy="4.71239265359 0 0" xyz="0.0875 0.026 0.02247"/>
        <axis xyz="0 0 -1.0"/>
        <limit effort="25" lower="-1.85349620283" upper="0.2" velocity="6.28318530718"/>
    </joint>
    <joint name="LF12" type="revolute">
        <parent link="Body_LF11"/>
        <child link="Body_LF12"/>
        <origin rpy="0 1.3963 0" xyz="0.041952 0 -0.002"/>
        <axis xyz="0 1.0 0"/>
        <limit effort="25" lower="-3.14159265359" upper="3.14159265359" velocity="6.28318530718"/>
	<mimic joint="LF1" />
	    
    </joint>
    <joint name="LF13" type="revolute">
        <parent link="Body_LF12"/>
        <child link="Body_LF13"/>
        <origin rpy="0 1.3963 0" xyz="0.029967 0 -0.0014"/>
        <axis xyz="0 1.0 0"/>
        <limit effort="25" lower="-3.14159265359" upper="3.14159265359" velocity="6.28318530718"/>
	<mimic joint="LF1" />
    </joint>
    <link name="Body_LF21">
        <visual>
            <geometry>
                <mesh filename="package://drchubo_v3/meshes/convhull_LF11.stl"/>
            </geometry>
            <origin rpy="0 0 0" xyz="0 0 0"/>
            <material name="">
                <color rgba="0.3 0.3 0.3 1.0"/>
            </material>
        </visual>
        <collision>
            <geometry>
                <mesh filename="package://drchubo_v3/meshes/convhull_LF11.stl"/>
            </geometry>
            <origin rpy="0 0 0" xyz="0 0 0"/>
        </collision>
        <inertial>
            <mass value="0.0263710648328"/>
            <inertia ixx="1.98396439062e-06" ixy="3.66951330319e-08" ixz="-7.82216813087e-08" iyy="6.90160086478e-06" iyz="-5.52885566501e-09" izz="6.59611827284e-06"/>
            <origin rpy="0 0 0" xyz="0.013675535045 0.000167665760228 0.000198749511991"/>
        </inertial>
    </link>
    <link name="Body_LF22">
        <visual>
            <geometry>
                <mesh filename="package://drchubo_v3/meshes/convhull_LF12_merged.stl"/>
            </geometry>
            <origin rpy="0 0 0" xyz="0 0 0"/>
            <material name="">
                <color rgba="0.3 0.3 0.3 1.0"/>
            </material>
        </visual>
        <collision>
            <geometry>
                <mesh filename="package://drchubo_v3/meshes/convhull_LF12_merged.stl"/>
            </geometry>
            <origin rpy="0 0 0" xyz="0 0 0"/>
        </collision>
        <inertial>
            <mass value="0.016189368249"/>
            <inertia ixx="1.30911370818e-06" ixy="1.49423602565e-08" ixz="-5.01486524729e-08" iyy="2.82043860524e-06" iyz="-2.8629444527e-09" izz="3.05888536891e-06"/>
            <origin rpy="0 0 0" xyz="0.0110393059886 0.000234060880175 5.56986057552e-05"/>
        </inertial>
    </link>
    <link name="Body_LF23">
        <visual>
            <geometry>
                <mesh filename="package://drchubo_v3/meshes/convhull_LF13_merged.stl"/>
            </geometry>
            <origin rpy="0 0 0" xyz="0 0 0"/>
            <material name="">
                <color rgba="0.3 0.3 0.3 1.0"/>
            </material>
        </visual>
        <collision>
            <geometry>
                <mesh filename="package://drchubo_v3/meshes/convhull_LF13_merged.stl"/>
            </geometry>
            <origin rpy="0 0 0" xyz="0 0 0"/>
        </collision>
        <inertial>
            <mass value="0.0182221650877"/>
            <inertia ixx="1.03181617487e-06" ixy="-4.94978359879e-08" ixz="-1.22492186704e-07" iyy="2.57254536616e-06" iyz="-5.58418574878e-09" izz="2.54656084717e-06"/>
            <origin rpy="0 0 0" xyz="0.0171497739791 -0.000431859131656 0.000224831410368"/>
        </inertial>
    </link>
    
    <joint name="LWR" type="revolute">
        <parent link="Body_LWP"/>
        <child link="Body_LWR"/>
        <origin rpy="0 0 0" xyz="0.027 -0.067 0"/>
        <axis xyz="-1.0 0 0"/>
        <limit effort="25" lower="-2.69956074975" upper="2.7000516236" velocity="6.28318530718"/>
    </joint>
    <joint name="LF21" type="revolute">
        <parent link="Body_LWR"/>
        <child link="Body_LF21"/>
        <origin rpy="1.57079265359 0 0" xyz="0.0875 -0.026 3e-05"/>
        <axis xyz="0 0 1.0"/>
        <limit effort="25" lower="-3.14159265359" upper="3.14159265359" velocity="6.28318530718"/>
	<mimic joint="LF1" />
    </joint>
    <joint name="LF22" type="revolute">
        <parent link="Body_LF21"/>
        <child link="Body_LF22"/>
        <origin rpy="0 1.3963 0" xyz="0.041952 0 -0.002"/>
        <axis xyz="0 1.0 0"/>
        <limit effort="25" lower="-3.14159265359" upper="3.14159265359" velocity="6.28318530718"/>
	<mimic joint="LF1" />
    </joint>
    <joint name="LF23" type="revolute">
        <parent link="Body_LF22"/>
        <child link="Body_LF23"/>
        <origin rpy="0 1.3963 0" xyz="0.029967 0 -0.0014"/>
        <axis xyz="0 1.0 0"/>
        <limit effort="25" lower="-3.14159265359" upper="3.14159265359" velocity="6.28318530718"/>
	<mimic joint="LF1" />
    </joint>
    <link name="Body_LF31">
        <visual>
            <geometry>
                <mesh filename="package://drchubo_v3/meshes/convhull_LF11.stl"/>
            </geometry>
            <origin rpy="0 0 0" xyz="0 0 0"/>
            <material name="">
                <color rgba="0.3 0.3 0.3 1.0"/>
            </material>
        </visual>
        <collision>
            <geometry>
                <mesh filename="package://drchubo_v3/meshes/convhull_LF11.stl"/>
            </geometry>
            <origin rpy="0 0 0" xyz="0 0 0"/>
        </collision>
        <inertial>
            <mass value="0.0263710648328"/>
            <inertia ixx="1.98396439062e-06" ixy="3.66951330319e-08" ixz="-7.82216813087e-08" iyy="6.90160086478e-06" iyz="-5.52885566502e-09" izz="6.59611827284e-06"/>
            <origin rpy="0 0 0" xyz="0.013675535045 0.000167665760228 0.000198749511991"/>
        </inertial>
    </link>
    <link name="Body_LF32">
        <visual>
            <geometry>
                <mesh filename="package://drchubo_v3/meshes/convhull_LF12_merged.stl"/>
            </geometry>
            <origin rpy="0 0 0" xyz="0 0 0"/>
            <material name="">
                <color rgba="0.3 0.3 0.3 1.0"/>
            </material>
        </visual>
        <collision>
            <geometry>
                <mesh filename="package://drchubo_v3/meshes/convhull_LF12_merged.stl"/>
            </geometry>
            <origin rpy="0 0 0" xyz="0 0 0"/>
        </collision>
        <inertial>
            <mass value="0.016189368249"/>
            <inertia ixx="1.30911370818e-06" ixy="1.49423602565e-08" ixz="-5.01486524729e-08" iyy="2.82043860524e-06" iyz="-2.8629444527e-09" izz="3.05888536891e-06"/>
            <origin rpy="0 0 0" xyz="0.0110393059886 0.000234060880175 5.56986057552e-05"/>
        </inertial>
    </link>
    <link name="Body_LF33">
        <visual>
            <geometry>
                <mesh filename="package://drchubo_v3/meshes/convhull_LF13_merged.stl"/>
            </geometry>
            <origin rpy="0 0 0" xyz="0 0 0"/>
            <material name="">
                <color rgba="0.3 0.3 0.3 1.0"/>
            </material>
        </visual>
        <collision>
            <geometry>
                <mesh filename="package://drchubo_v3/meshes/convhull_LF13_merged.stl"/>
            </geometry>
            <origin rpy="0 0 0" xyz="0 0 0"/>
        </collision>
        <inertial>
            <mass value="0.0182221650877"/>
            <inertia ixx="1.03181617487e-06" ixy="-4.94978359879e-08" ixz="-1.22492186704e-07" iyy="2.57254536616e-06" iyz="-5.58418574879e-09" izz="2.54656084717e-06"/>
            <origin rpy="0 0 0" xyz="0.0171497739791 -0.000431859131656 0.000224831410368"/>
        </inertial>
    </link>
    <joint name="LF31" type="revolute">
        <parent link="Body_LWR"/>
        <child link="Body_LF31"/>
        <origin rpy="4.71239265359 0 0" xyz="0.0875 0.026 -0.02247"/>
        <axis xyz="0 0 -1.0"/>
        <limit effort="25" lower="-3.14159265359" upper="3.14159265359" velocity="6.28318530718"/>
	<mimic joint="LF1" />
    </joint>
    <joint name="LF32" type="revolute">
        <parent link="Body_LF31"/>
        <child link="Body_LF32"/>
        <origin rpy="0 1.3963 0" xyz="0.041952 0 -0.002"/>
        <axis xyz="0 1.0 0"/>
        <limit effort="25" lower="-3.14159265359" upper="3.14159265359" velocity="6.28318530718"/>
	<mimic joint="LF1" />
    </joint>
    <joint name="LF33" type="revolute">
        <parent link="Body_LF32"/>
        <child link="Body_LF33"/>
        <origin rpy="0 1.3963 0" xyz="0.029967 0 -0.0014"/>
        <axis xyz="0 1.0 0"/>
        <limit effort="25" lower="-3.14159265359" upper="3.14159265359" velocity="6.28318530718"/>
	<mimic joint="LF1" />
    </joint>
</robot>
